<?xml version="1.0" ?>
<!-- =================================================================================== -->
<!-- |    This document was autogenerated by xacro from panda_arm_hand.urdf.xacro      | -->
<!-- |    EDITING THIS FILE BY HAND IS NOT RECOMMENDED                                 | -->
<!-- =================================================================================== -->
<robot name="panda" xmlns:xacro="http://www.ros.org/wiki/xacro">
 
  <link name="panda_hand">
  	<inertial>
      <origin rpy="0 0 0" xyz="0.001540105015344	0.001492254522239	0.002826647554898"/>
       <mass value=".81"/>
       <inertia ixx="0.1" ixy="0" ixz="0" iyy="0.1" iyz="0" izz="0.1"/>
    </inertial>
    <visual>
      <geometry>
        <mesh filename="./meshes/visual/hand.obj"/>
      </geometry>
      <material name="panda_white"/>
    </visual>
    <collision>
      <geometry>
        <mesh filename="./meshes/collision/hand.obj"/>
      </geometry>
      <material name="panda_white"/>
    </collision>
  </link>
  <link name="panda_leftfinger">
    <inertial>
      <mass value="0.099" />
      <origin rpy="0 0 0" xyz="0 0.029 0.0545" />
      <inertia ixx="0.000135" ixy="0.0" ixz="0.0" iyy="0.000128" iyz="0.000012" izz="0.000021" />
    </inertial>
    <visual>
      <!-- Translation chosen so that the finger visuals exactly meet in the
            middle of the gripper just as they do on hardware.
        -->
      <origin rpy="0 0 0" xyz="0 0.01 0" />
      <geometry>
        <mesh filename="franka_fr3/finray_finger_L.obj" scale="1 1 1" />
      </geometry>
    </visual>
    <collision name="finray_finger_L_mount_collision">
      <origin rpy="0 0 -1.57079632679" xyz="0 0.01 0" />
      <geometry>
        <mesh filename="franka_fr3/finray_finger_L_mount_low.obj" scale="1 1 1" />
      </geometry>
    </collision>
    <collision name="finray_finger_L_body_collision">
      <origin rpy="0 0 -1.57079632679" xyz="0 0.01 0" />
      <geometry>
        <mesh filename="franka_fr3/finray_finger_L.obj" scale="1 1 1" />
      </geometry>
    </collision>
  </link>
  <link name="panda_rightfinger">
    <inertial>
      <mass value="0.099" />
      <origin rpy="0 0 0" xyz="0 -0.029 0.0545" />
      <inertia ixx="0.000135" ixy="0.0" ixz="0.0" iyy="0.000128" iyz="-0.000012" izz="0.000021" />
    </inertial>
    <visual>
      <!-- Translation chosen so that the finger visuals exactly meet in the
            middle of the gripper just as they do on hardware.
        -->
      <origin rpy="0 0 0" xyz="0 -0.01 0" />
      <geometry>
        <mesh filename="franka_fr3/finray_finger_R.obj" scale="1 1 1" />
      </geometry>
    </visual>
    <collision name="finray_finger_R_mount_collision">
      <origin rpy="0 0 -1.57079632679" xyz="0 -0.01 0" />
      <geometry>
        <mesh filename="franka_fr3/finray_finger_R_mount_low.obj" scale="1 1 1" />
      </geometry>
    </collision>
    <collision name="finray_finger_R_body_collision">
      <origin rpy="0 0 -1.57079632679" xyz="0 -0.01 0" />
      <geometry>
        <mesh filename="franka_fr3/finray_finger_R.obj" scale="1 1 1" />
      </geometry>
    </collision>
  </link>
  <joint name="panda_finger_joint1" type="prismatic">
    <parent link="panda_hand" />
    <child link="panda_leftfinger" />
    <origin rpy="0 0 0" xyz="0 -0.01 0.0584" />
    <axis xyz="0 1 0" />
    <limit effort="20" lower="0.0" upper="0.041" velocity="0.2" />
  </joint>
  <joint name="panda_finger_joint2" type="prismatic">
    <parent link="panda_hand" />
    <child link="panda_rightfinger" />
    <origin rpy="0 0 0" xyz="0 0.01 0.0584" />
    <axis xyz="0 1 0" />
    <limit effort="20" lower="-0.041" upper="0.0" velocity="0.2" />
  </joint>
  <link name="panda_grasptarget">
    <inertial>
      <origin rpy="0 0 0" xyz="0 0 0"/>
       <mass value="0.0"/>
       <inertia ixx="0.1" ixy="0" ixz="0" iyy="0.1" iyz="0" izz="0.1"/>
    </inertial>
  </link>
  <joint name="panda_grasptarget_hand" type="fixed">
    <parent link="panda_hand"/>
    <child link="panda_grasptarget"/>
    <origin rpy="0 0 0" xyz="0 0 0.105"/>
  </joint>
  
</robot>